{
 "cells": [
  {
   "cell_type": "markdown",
   "metadata": {},
   "source": [
    "<a href=\"https://colab.research.google.com/github/fralfaro/python_intro/blob/main/docs/error.ipynb\" target=\"_parent\"><img src=\"https://colab.research.google.com/assets/colab-badge.svg\" alt=\"Open In Colab\"/></a>"
   ]
  },
  {
   "cell_type": "markdown",
   "metadata": {},
   "source": [
    "# Excepciones"
   ]
  },
  {
   "cell_type": "markdown",
   "metadata": {},
   "source": [
    "<div style=\"display: flex; justify-content: center;\">\n",
    "    <img src=\"https://teachen.info/cspp/_images/errormsg.svg\" alt=\"fishy\" width=\"700px\">\n",
    "</div>"
   ]
  },
  {
   "cell_type": "markdown",
   "metadata": {},
   "source": [
    "## Introducción"
   ]
  },
  {
   "cell_type": "markdown",
   "metadata": {},
   "source": [
    "Existen muchos tipos de errores que pueden estar presentes en un programa. No todos los errores pueden ser detectados por el computador. Veamos el siguiente ejemplo:"
   ]
  },
  {
   "cell_type": "code",
   "execution_count": 1,
   "metadata": {},
   "outputs": [
    {
     "name": "stdout",
     "output_type": "stream",
     "text": [
      "El doble de n es 12\n"
     ]
    }
   ],
   "source": [
    "# error semantico\n",
    "n = 4\n",
    "doble = 3 * n\n",
    "print(f'El doble de n es {doble}')"
   ]
  },
  {
   "cell_type": "markdown",
   "metadata": {},
   "source": [
    "El computador no se dará cuenta del error, pues todas las instrucciones del programa son correctas. El programa simplemente entregará siempre la respuesta equivocada.\n",
    "\n",
    "Existen otros errores que sí pueden ser detectados: las **excepciones**. Las excepciones son errores que se producen durante la ejecución de un programa, como por ejemplo un error de sintaxis, un archivo que no se puede abrir o un valor que no se puede dividir por cero. \n",
    "\n",
    "* Si no se manejan las excepciones, se imprime un mensaje de error y nuestro programa se detiene repentinamente e inesperadamente. \n",
    "\n",
    "* Existen varios tipos de  [excepciones](https://docs.python.org/3/library/exceptions.html), sin embargo, en esta sección se presentan algunas de ellas."
   ]
  },
  {
   "cell_type": "markdown",
   "metadata": {},
   "source": [
    "## Tipos de Errores\n",
    "\n",
    "### Error de sintaxis\n",
    "\n",
    "Un error de sintaxis ocurre cuando el programa no cumple las reglas del lenguaje. Cuando ocurre este error, significa que el programa está mal escrito. El nombre del error es `SyntaxError`."
   ]
  },
  {
   "cell_type": "code",
   "execution_count": 2,
   "metadata": {},
   "outputs": [
    {
     "ename": "SyntaxError",
     "evalue": "unmatched ')' (676501493.py, line 2)",
     "output_type": "error",
     "traceback": [
      "\u001b[1;36m  Input \u001b[1;32mIn [2]\u001b[1;36m\u001b[0m\n\u001b[1;33m    2 * (3 + 4))\u001b[0m\n\u001b[1;37m               ^\u001b[0m\n\u001b[1;31mSyntaxError\u001b[0m\u001b[1;31m:\u001b[0m unmatched ')'\n"
     ]
    }
   ],
   "source": [
    "# SyntaxError\n",
    "2 * (3 + 4))"
   ]
  },
  {
   "cell_type": "markdown",
   "metadata": {},
   "source": [
    "### Error de nombre\n",
    "\n",
    "Un error de nombre ocurre al usar una variable que no ha sido creada con anterioridad. El nombre de la excepción es `NameError`."
   ]
  },
  {
   "cell_type": "code",
   "execution_count": 3,
   "metadata": {},
   "outputs": [
    {
     "ename": "NameError",
     "evalue": "name 'y' is not defined",
     "output_type": "error",
     "traceback": [
      "\u001b[1;31m---------------------------------------------------------------------------\u001b[0m",
      "\u001b[1;31mNameError\u001b[0m                                 Traceback (most recent call last)",
      "Input \u001b[1;32mIn [3]\u001b[0m, in \u001b[0;36m<cell line: 3>\u001b[1;34m()\u001b[0m\n\u001b[0;32m      1\u001b[0m \u001b[38;5;66;03m# NameError\u001b[39;00m\n\u001b[0;32m      2\u001b[0m x \u001b[38;5;241m=\u001b[39m \u001b[38;5;241m20\u001b[39m\n\u001b[1;32m----> 3\u001b[0m x\u001b[38;5;241m+\u001b[39m\u001b[43my\u001b[49m\n",
      "\u001b[1;31mNameError\u001b[0m: name 'y' is not defined"
     ]
    }
   ],
   "source": [
    "# NameError\n",
    "x = 20\n",
    "x+y"
   ]
  },
  {
   "cell_type": "markdown",
   "metadata": {},
   "source": [
    "### Error de tipo\n",
    "En general, todas las operaciones en un programa pueden ser aplicadas sobre valores de tipos bien específicos. Un error de tipo ocurre al aplicar una operación sobre operandos de tipo incorrecto.\n",
    "\n",
    "El nombre de la excepción es `TypeError`."
   ]
  },
  {
   "cell_type": "code",
   "execution_count": 4,
   "metadata": {},
   "outputs": [
    {
     "ename": "TypeError",
     "evalue": "can't multiply sequence by non-int of type 'str'",
     "output_type": "error",
     "traceback": [
      "\u001b[1;31m---------------------------------------------------------------------------\u001b[0m",
      "\u001b[1;31mTypeError\u001b[0m                                 Traceback (most recent call last)",
      "Input \u001b[1;32mIn [4]\u001b[0m, in \u001b[0;36m<cell line: 2>\u001b[1;34m()\u001b[0m\n\u001b[0;32m      1\u001b[0m \u001b[38;5;66;03m# type error\u001b[39;00m\n\u001b[1;32m----> 2\u001b[0m \u001b[38;5;124;43m'\u001b[39;49m\u001b[38;5;124;43mseis\u001b[39;49m\u001b[38;5;124;43m'\u001b[39;49m\u001b[43m \u001b[49m\u001b[38;5;241;43m*\u001b[39;49m\u001b[43m \u001b[49m\u001b[38;5;124;43m'\u001b[39;49m\u001b[38;5;124;43mocho\u001b[39;49m\u001b[38;5;124;43m'\u001b[39;49m\n",
      "\u001b[1;31mTypeError\u001b[0m: can't multiply sequence by non-int of type 'str'"
     ]
    }
   ],
   "source": [
    "# type error\n",
    "'seis' * 'ocho'"
   ]
  },
  {
   "cell_type": "markdown",
   "metadata": {},
   "source": [
    "### Error de valor\n",
    "El error de valor ocurre cuando los operandos son del tipo correcto, pero la operación no tiene sentido para ese valor. El nombre de la excepción es `ValueError`."
   ]
  },
  {
   "cell_type": "code",
   "execution_count": 5,
   "metadata": {},
   "outputs": [
    {
     "ename": "ValueError",
     "evalue": "invalid literal for int() with base 10: 'perro'",
     "output_type": "error",
     "traceback": [
      "\u001b[1;31m---------------------------------------------------------------------------\u001b[0m",
      "\u001b[1;31mValueError\u001b[0m                                Traceback (most recent call last)",
      "Input \u001b[1;32mIn [5]\u001b[0m, in \u001b[0;36m<cell line: 2>\u001b[1;34m()\u001b[0m\n\u001b[0;32m      1\u001b[0m \u001b[38;5;66;03m# ValueError\u001b[39;00m\n\u001b[1;32m----> 2\u001b[0m \u001b[38;5;28;43mint\u001b[39;49m\u001b[43m(\u001b[49m\u001b[38;5;124;43m'\u001b[39;49m\u001b[38;5;124;43mperro\u001b[39;49m\u001b[38;5;124;43m'\u001b[39;49m\u001b[43m)\u001b[49m\n",
      "\u001b[1;31mValueError\u001b[0m: invalid literal for int() with base 10: 'perro'"
     ]
    }
   ],
   "source": [
    "# ValueError\n",
    "int('perro')"
   ]
  },
  {
   "cell_type": "markdown",
   "metadata": {},
   "source": [
    "### Error de división por cero\n",
    "El error de division por cero ocurre al intentar dividir por cero. El nombre de la excepción es `ZeroDivisionError`:"
   ]
  },
  {
   "cell_type": "code",
   "execution_count": 6,
   "metadata": {},
   "outputs": [
    {
     "ename": "ZeroDivisionError",
     "evalue": "division by zero",
     "output_type": "error",
     "traceback": [
      "\u001b[1;31m---------------------------------------------------------------------------\u001b[0m",
      "\u001b[1;31mZeroDivisionError\u001b[0m                         Traceback (most recent call last)",
      "Input \u001b[1;32mIn [6]\u001b[0m, in \u001b[0;36m<cell line: 2>\u001b[1;34m()\u001b[0m\n\u001b[0;32m      1\u001b[0m \u001b[38;5;66;03m# ZeroDivisionError\u001b[39;00m\n\u001b[1;32m----> 2\u001b[0m \u001b[38;5;241;43m1\u001b[39;49m\u001b[38;5;241;43m/\u001b[39;49m\u001b[38;5;241;43m0\u001b[39;49m\n",
      "\u001b[1;31mZeroDivisionError\u001b[0m: division by zero"
     ]
    }
   ],
   "source": [
    "# ZeroDivisionError\n",
    "1/0"
   ]
  },
  {
   "cell_type": "markdown",
   "metadata": {},
   "source": [
    "### Error de desborde\n",
    "\n",
    "El error de desborde ocurre cuando el resultado de una operación es tan grande que el computador no puede representarlo internamente.\n",
    "\n",
    "El nombre de la excepción es `OverflowError`."
   ]
  },
  {
   "cell_type": "code",
   "execution_count": 7,
   "metadata": {},
   "outputs": [
    {
     "ename": "OverflowError",
     "evalue": "(34, 'Result too large')",
     "output_type": "error",
     "traceback": [
      "\u001b[1;31m---------------------------------------------------------------------------\u001b[0m",
      "\u001b[1;31mOverflowError\u001b[0m                             Traceback (most recent call last)",
      "Input \u001b[1;32mIn [7]\u001b[0m, in \u001b[0;36m<cell line: 2>\u001b[1;34m()\u001b[0m\n\u001b[0;32m      1\u001b[0m \u001b[38;5;66;03m# OverflowError\u001b[39;00m\n\u001b[1;32m----> 2\u001b[0m \u001b[38;5;241;43m20.0\u001b[39;49m\u001b[43m \u001b[49m\u001b[38;5;241;43m*\u001b[39;49m\u001b[38;5;241;43m*\u001b[39;49m\u001b[43m \u001b[49m\u001b[38;5;241;43m20.0\u001b[39;49m\u001b[43m \u001b[49m\u001b[38;5;241;43m*\u001b[39;49m\u001b[38;5;241;43m*\u001b[39;49m\u001b[43m \u001b[49m\u001b[38;5;241;43m20.0\u001b[39;49m\n",
      "\u001b[1;31mOverflowError\u001b[0m: (34, 'Result too large')"
     ]
    }
   ],
   "source": [
    "# OverflowError\n",
    "20.0 ** 20.0 ** 20.0"
   ]
  },
  {
   "cell_type": "markdown",
   "metadata": {},
   "source": [
    "## Raise\n",
    "\n",
    "En Python, el comando `raise` se emplea para generar excepciones de forma deliberada en un programa. En otras palabras, permite al programador desencadenar una excepción en un momento específico del programa en lugar de esperar a que ocurra de manera automática.\n",
    "\n",
    "La sintaxis del comando `raise` es la siguiente:\n",
    "```python\n",
    "raise ExceptionType(\"Mensaje de error\")\n",
    "```\n",
    "\n",
    "En esta sintaxis, `ExceptionType` se refiere al tipo de excepción que se desea desencadenar, y `\"Mensaje de error\"` es un mensaje opcional que proporciona información adicional sobre la excepción.\n",
    "\n",
    "Por ejemplo, supongamos que deseas generar una excepción de tipo `ValueError` cuando te encuentres con un valor numérico negativo. Puedes lograrlo de la siguiente manera:"
   ]
  },
  {
   "cell_type": "code",
   "execution_count": 12,
   "metadata": {},
   "outputs": [],
   "source": [
    "def funcion(num):\n",
    "    if num < 0:\n",
    "        raise ValueError(\"El valor no puede ser negativo\")\n",
    "    else:\n",
    "        return num"
   ]
  },
  {
   "cell_type": "markdown",
   "metadata": {},
   "source": [
    "En este ejemplo, si el valor de `num` es negativo, se genera una excepción de tipo `ValueError` con el mensaje \"El valor no puede ser negativo\". De lo contrario, la función devuelve el valor de `num`."
   ]
  },
  {
   "cell_type": "code",
   "execution_count": 13,
   "metadata": {},
   "outputs": [
    {
     "data": {
      "text/plain": [
       "1"
      ]
     },
     "execution_count": 13,
     "metadata": {},
     "output_type": "execute_result"
    }
   ],
   "source": [
    "funcion(1)"
   ]
  },
  {
   "cell_type": "code",
   "execution_count": 14,
   "metadata": {},
   "outputs": [
    {
     "ename": "ValueError",
     "evalue": "El valor no puede ser negativo",
     "output_type": "error",
     "traceback": [
      "\u001b[1;31m---------------------------------------------------------------------------\u001b[0m",
      "\u001b[1;31mValueError\u001b[0m                                Traceback (most recent call last)",
      "Input \u001b[1;32mIn [14]\u001b[0m, in \u001b[0;36m<cell line: 1>\u001b[1;34m()\u001b[0m\n\u001b[1;32m----> 1\u001b[0m \u001b[43mfuncion\u001b[49m\u001b[43m(\u001b[49m\u001b[38;5;241;43m-\u001b[39;49m\u001b[38;5;241;43m1\u001b[39;49m\u001b[43m)\u001b[49m\n",
      "Input \u001b[1;32mIn [12]\u001b[0m, in \u001b[0;36mfuncion\u001b[1;34m(num)\u001b[0m\n\u001b[0;32m      1\u001b[0m \u001b[38;5;28;01mdef\u001b[39;00m \u001b[38;5;21mfuncion\u001b[39m(num):\n\u001b[0;32m      2\u001b[0m     \u001b[38;5;28;01mif\u001b[39;00m num \u001b[38;5;241m<\u001b[39m \u001b[38;5;241m0\u001b[39m:\n\u001b[1;32m----> 3\u001b[0m         \u001b[38;5;28;01mraise\u001b[39;00m \u001b[38;5;167;01mValueError\u001b[39;00m(\u001b[38;5;124m\"\u001b[39m\u001b[38;5;124mEl valor no puede ser negativo\u001b[39m\u001b[38;5;124m\"\u001b[39m)\n\u001b[0;32m      4\u001b[0m     \u001b[38;5;28;01melse\u001b[39;00m:\n\u001b[0;32m      5\u001b[0m         \u001b[38;5;28;01mreturn\u001b[39;00m num\n",
      "\u001b[1;31mValueError\u001b[0m: El valor no puede ser negativo"
     ]
    }
   ],
   "source": [
    "funcion(-1)"
   ]
  },
  {
   "cell_type": "markdown",
   "metadata": {},
   "source": [
    "**Conclusión**\n",
    "\n",
    "Existen dos maneras para lanzar una excepción:\n",
    "\n",
    "* Hacer una operación que no puede ser realizada (como dividir por cero). En este caso Python se encarga de lanzar automáticamente la excepción.\n",
    "* Lanzar nosotros una excepción manualmente, usando `raise`."
   ]
  },
  {
   "cell_type": "markdown",
   "metadata": {},
   "source": [
    "> **Nota**: El comando `raise` es útil cuando se desea interrumpir el flujo normal de un programa y provocar una excepción en un punto específico. Sin embargo, se debe utilizar con precaución, ya que puede dificultar la depuración del programa si se utiliza en exceso o de manera incorrecta."
   ]
  },
  {
   "cell_type": "markdown",
   "metadata": {},
   "source": [
    "## Menajando excepciones: Try/Except\n",
    "\n",
    "En Python, las excepciones se pueden manejar usando la declaración `try`. Cuando se detectan excepciones, depende de usted qué operador realizar."
   ]
  },
  {
   "cell_type": "code",
   "execution_count": 10,
   "metadata": {},
   "outputs": [
    {
     "name": "stdout",
     "output_type": "stream",
     "text": [
      "No se puede dividir entre cero\n"
     ]
    }
   ],
   "source": [
    "try:\n",
    "    x = 1 / 0\n",
    "except:\n",
    "    print(\"No se puede dividir entre cero\")"
   ]
  },
  {
   "cell_type": "markdown",
   "metadata": {},
   "source": [
    "En este ejemplo, se intenta dividir el número `1` entre `0`. Como no se puede realizar la división, se produce una excepción de tipo `ZeroDivisionError`.\n",
    "\n",
    "Por otro lado, también se puede especificar en el `except` el tipo de error."
   ]
  },
  {
   "cell_type": "code",
   "execution_count": 11,
   "metadata": {},
   "outputs": [
    {
     "name": "stdout",
     "output_type": "stream",
     "text": [
      "No se puede dividir entre cero\n"
     ]
    }
   ],
   "source": [
    "try:\n",
    "    x = 1 / 0\n",
    "except ZeroDivisionError:\n",
    "    print(\"No se puede dividir entre cero\")"
   ]
  },
  {
   "cell_type": "markdown",
   "metadata": {},
   "source": [
    "**Uso de else**\n",
    "\n",
    "Al ya explicado `try` y `except` le podemos añadir un bloque más, el `else`. Dicho bloque se ejecutará si no ha ocurrido ninguna excepción. Fíjate en la diferencia entre los siguientes códigos."
   ]
  },
  {
   "cell_type": "code",
   "execution_count": 8,
   "metadata": {},
   "outputs": [
    {
     "name": "stdout",
     "output_type": "stream",
     "text": [
      "Entra en except, ha ocurrido una excepción\n"
     ]
    }
   ],
   "source": [
    "try:\n",
    "    # Forzamos una excepción al dividir entre 0\n",
    "    x = 2/0\n",
    "except:\n",
    "    print(\"Entra en except, ha ocurrido una excepción\")\n",
    "else:\n",
    "    print(\"Entra en else, no ha ocurrido ninguna excepción\")\n"
   ]
  },
  {
   "cell_type": "markdown",
   "metadata": {},
   "source": [
    "Sin embargo en el siguiente código la división se puede realizar sin problema, por lo que el bloque `except` no se ejecuta pero el `else` si es ejecutado."
   ]
  },
  {
   "cell_type": "code",
   "execution_count": 9,
   "metadata": {},
   "outputs": [
    {
     "name": "stdout",
     "output_type": "stream",
     "text": [
      "Entra en else, no ha ocurrido ninguna excepción\n"
     ]
    }
   ],
   "source": [
    "try:\n",
    "    # La división puede realizarse sin problema\n",
    "    x = 2/2\n",
    "except:\n",
    "    print(\"Entra en except, ha ocurrido una excepción\")\n",
    "else:\n",
    "    print(\"Entra en else, no ha ocurrido ninguna excepción\")"
   ]
  },
  {
   "cell_type": "markdown",
   "metadata": {},
   "source": [
    "## Aserciones en python\n",
    "\n",
    "Las aserciones  son expresiones booleanas que comprueban si las condiciones devuelven verdaderas o no. Si es cierto, el programa no hace nada y pasa a la siguiente línea de código. Sin embargo, si es falso, el programa se detiene y arroja un error.\n",
    "\n",
    "Las aserciones son importantes al momento de realizar **tests unitarios** o asegurar que un resultado siempre sea el mismo.\n",
    "\n",
    "<img src=\"https://raw.githubusercontent.com/fralfaro/python_intro/main/docs/images/assert.jpg\" alt=\"\" width=\"400\" align=\"center\" />"
   ]
  },
  {
   "cell_type": "markdown",
   "metadata": {},
   "source": [
    "###  assert en funciones\n",
    "\n",
    "Puede resultar útil usar `assert(`) cuando queremos realizar alguna comprobación, como podría ser dentro de una función. En el siguiente ejemplo tenemos una función `suma()` que sólo suma las variables si son números enteros."
   ]
  },
  {
   "cell_type": "code",
   "execution_count": 18,
   "metadata": {},
   "outputs": [],
   "source": [
    "# Funcion suma de variables enteras\n",
    "def suma(a, b):\n",
    "    assert(type(a) == int), \"el primer valor ingresado no es entero\"\n",
    "    assert(type(b) == int), \"el segundo valor ingresado no es entero\"\n",
    "    return a+b"
   ]
  },
  {
   "cell_type": "code",
   "execution_count": 19,
   "metadata": {},
   "outputs": [
    {
     "data": {
      "text/plain": [
       "8"
      ]
     },
     "execution_count": 19,
     "metadata": {},
     "output_type": "execute_result"
    }
   ],
   "source": [
    "# Ok, los argumentos son int\n",
    "suma(3, 5)"
   ]
  },
  {
   "cell_type": "code",
   "execution_count": 20,
   "metadata": {},
   "outputs": [
    {
     "ename": "AssertionError",
     "evalue": "el primer valor ingresado no es entero",
     "output_type": "error",
     "traceback": [
      "\u001b[1;31m---------------------------------------------------------------------------\u001b[0m",
      "\u001b[1;31mAssertionError\u001b[0m                            Traceback (most recent call last)",
      "Input \u001b[1;32mIn [20]\u001b[0m, in \u001b[0;36m<cell line: 2>\u001b[1;34m()\u001b[0m\n\u001b[0;32m      1\u001b[0m \u001b[38;5;66;03m# Error, ya que las variables no son int\u001b[39;00m\n\u001b[1;32m----> 2\u001b[0m \u001b[43msuma\u001b[49m\u001b[43m(\u001b[49m\u001b[38;5;241;43m3.0\u001b[39;49m\u001b[43m,\u001b[49m\u001b[43m \u001b[49m\u001b[38;5;241;43m5.0\u001b[39;49m\u001b[43m)\u001b[49m\n",
      "Input \u001b[1;32mIn [18]\u001b[0m, in \u001b[0;36msuma\u001b[1;34m(a, b)\u001b[0m\n\u001b[0;32m      2\u001b[0m \u001b[38;5;28;01mdef\u001b[39;00m \u001b[38;5;21msuma\u001b[39m(a, b):\n\u001b[1;32m----> 3\u001b[0m     \u001b[38;5;28;01massert\u001b[39;00m(\u001b[38;5;28mtype\u001b[39m(a) \u001b[38;5;241m==\u001b[39m \u001b[38;5;28mint\u001b[39m), \u001b[38;5;124m\"\u001b[39m\u001b[38;5;124mel primer valor ingresado no es entero\u001b[39m\u001b[38;5;124m\"\u001b[39m\n\u001b[0;32m      4\u001b[0m     \u001b[38;5;28;01massert\u001b[39;00m(\u001b[38;5;28mtype\u001b[39m(b) \u001b[38;5;241m==\u001b[39m \u001b[38;5;28mint\u001b[39m), \u001b[38;5;124m\"\u001b[39m\u001b[38;5;124mel segundo valor ingresado no es entero\u001b[39m\u001b[38;5;124m\"\u001b[39m\n\u001b[0;32m      5\u001b[0m     \u001b[38;5;28;01mreturn\u001b[39;00m a\u001b[38;5;241m+\u001b[39mb\n",
      "\u001b[1;31mAssertionError\u001b[0m: el primer valor ingresado no es entero"
     ]
    }
   ],
   "source": [
    "# Error, ya que las variables no son int\n",
    "suma(3.0, 5)"
   ]
  },
  {
   "cell_type": "code",
   "execution_count": 21,
   "metadata": {},
   "outputs": [
    {
     "ename": "AssertionError",
     "evalue": "el segundo valor ingresado no es entero",
     "output_type": "error",
     "traceback": [
      "\u001b[1;31m---------------------------------------------------------------------------\u001b[0m",
      "\u001b[1;31mAssertionError\u001b[0m                            Traceback (most recent call last)",
      "Input \u001b[1;32mIn [21]\u001b[0m, in \u001b[0;36m<cell line: 2>\u001b[1;34m()\u001b[0m\n\u001b[0;32m      1\u001b[0m \u001b[38;5;66;03m# Error, ya que las variables no son int\u001b[39;00m\n\u001b[1;32m----> 2\u001b[0m \u001b[43msuma\u001b[49m\u001b[43m(\u001b[49m\u001b[38;5;241;43m3\u001b[39;49m\u001b[43m,\u001b[49m\u001b[43m \u001b[49m\u001b[38;5;241;43m5.0\u001b[39;49m\u001b[43m)\u001b[49m\n",
      "Input \u001b[1;32mIn [18]\u001b[0m, in \u001b[0;36msuma\u001b[1;34m(a, b)\u001b[0m\n\u001b[0;32m      2\u001b[0m \u001b[38;5;28;01mdef\u001b[39;00m \u001b[38;5;21msuma\u001b[39m(a, b):\n\u001b[0;32m      3\u001b[0m     \u001b[38;5;28;01massert\u001b[39;00m(\u001b[38;5;28mtype\u001b[39m(a) \u001b[38;5;241m==\u001b[39m \u001b[38;5;28mint\u001b[39m), \u001b[38;5;124m\"\u001b[39m\u001b[38;5;124mel primer valor ingresado no es entero\u001b[39m\u001b[38;5;124m\"\u001b[39m\n\u001b[1;32m----> 4\u001b[0m     \u001b[38;5;28;01massert\u001b[39;00m(\u001b[38;5;28mtype\u001b[39m(b) \u001b[38;5;241m==\u001b[39m \u001b[38;5;28mint\u001b[39m), \u001b[38;5;124m\"\u001b[39m\u001b[38;5;124mel segundo valor ingresado no es entero\u001b[39m\u001b[38;5;124m\"\u001b[39m\n\u001b[0;32m      5\u001b[0m     \u001b[38;5;28;01mreturn\u001b[39;00m a\u001b[38;5;241m+\u001b[39mb\n",
      "\u001b[1;31mAssertionError\u001b[0m: el segundo valor ingresado no es entero"
     ]
    }
   ],
   "source": [
    "# Error, ya que las variables no son int\n",
    "suma(3, 5.0)"
   ]
  },
  {
   "cell_type": "markdown",
   "metadata": {},
   "source": [
    "###  assert en testing\n",
    "\n",
    "La función `assert()` puede ser también muy útil para escribir tests unitarios o units tests. Veamos un ejemplo."
   ]
  },
  {
   "cell_type": "code",
   "execution_count": 22,
   "metadata": {},
   "outputs": [],
   "source": [
    "# definir funcion\n",
    "def suma(x,y):\n",
    "    return x+y"
   ]
  },
  {
   "cell_type": "code",
   "execution_count": 23,
   "metadata": {},
   "outputs": [],
   "source": [
    "# ejemplo correcto\n",
    "assert suma(1,1)==2, \"ejemplo invalido\""
   ]
  },
  {
   "cell_type": "code",
   "execution_count": 24,
   "metadata": {},
   "outputs": [
    {
     "ename": "AssertionError",
     "evalue": "ejemplo invalido",
     "output_type": "error",
     "traceback": [
      "\u001b[1;31m---------------------------------------------------------------------------\u001b[0m",
      "\u001b[1;31mAssertionError\u001b[0m                            Traceback (most recent call last)",
      "Input \u001b[1;32mIn [24]\u001b[0m, in \u001b[0;36m<cell line: 2>\u001b[1;34m()\u001b[0m\n\u001b[0;32m      1\u001b[0m \u001b[38;5;66;03m# ejemplo incorrecto\u001b[39;00m\n\u001b[1;32m----> 2\u001b[0m \u001b[38;5;28;01massert\u001b[39;00m suma(\u001b[38;5;241m1\u001b[39m,\u001b[38;5;241m1\u001b[39m)\u001b[38;5;241m==\u001b[39m\u001b[38;5;241m3\u001b[39m, \u001b[38;5;124m\"\u001b[39m\u001b[38;5;124mejemplo invalido\u001b[39m\u001b[38;5;124m\"\u001b[39m\n",
      "\u001b[1;31mAssertionError\u001b[0m: ejemplo invalido"
     ]
    }
   ],
   "source": [
    "# ejemplo incorrecto\n",
    "assert suma(1,1)==3, \"ejemplo invalido\""
   ]
  },
  {
   "cell_type": "markdown",
   "metadata": {},
   "source": [
    "## Warnings\n",
    "\n",
    "En Python, un [warnings](https://docs.python.org/3/library/warnings.html) es un mensaje que se muestra en la consola o en el registro de errores durante la ejecución del código para alertar al programador sobre un posible problema o una situación inusual que podría resultar en un error o un comportamiento no deseado en el programa.\n",
    "\n",
    "A diferencia de los errores (que interrumpen la ejecución del programa), los warnings son mensajes informativos que no impiden la ejecución del código, pero deben ser revisados y atendidos por el programador para garantizar la calidad del software.\n",
    "\n",
    "Por ejemplo, Python puede mostrar una advertencia si estás utilizando una función que se ha quedado obsoleta o que será eliminada en futuras versiones de Python, o si estás realizando una operación que puede tener efectos secundarios no deseados.\n",
    "\n",
    "Es importante prestar atención a las advertencias y abordarlas en consecuencia para asegurarse de que el código funcione de manera correcta y eficiente.\n",
    "\n",
    "Veamos un ejemplo:\n"
   ]
  },
  {
   "cell_type": "code",
   "execution_count": 24,
   "metadata": {},
   "outputs": [
    {
     "name": "stdout",
     "output_type": "stream",
     "text": [
      "Python\n",
      "Python!\n"
     ]
    },
    {
     "name": "stderr",
     "output_type": "stream",
     "text": [
      "C:\\Users\\franc\\AppData\\Local\\Temp\\ipykernel_3104\\3783018248.py:6: UserWarning: Atencion, esto es un warning!\n",
      "  warnings.warn('Atencion, esto es un warning!')\n"
     ]
    }
   ],
   "source": [
    "import warnings\n",
    "  \n",
    "print('Python')\n",
    "  \n",
    "# mostrar un mensaje warning \n",
    "warnings.warn('Atencion, esto es un warning!')\n",
    "  \n",
    "print('Python!')"
   ]
  },
  {
   "cell_type": "markdown",
   "metadata": {},
   "source": [
    "En este ejemplo, la función `warn()` se utiliza para mostrar el mensajede advertencia: \"Atencion, esto es un warning!\"."
   ]
  },
  {
   "cell_type": "markdown",
   "metadata": {},
   "source": [
    "### Tipos de Warnings\n",
    "\n"
   ]
  },
  {
   "cell_type": "markdown",
   "metadata": {},
   "source": [
    "**DeprecationWarning**\n",
    "\n",
    "Es un tipo de advertencia que se utiliza para indicar que una característica o función del lenguaje o biblioteca que se está utilizando está obsoleta y se eliminará en futuras versiones. Esta advertencia se emite para permitir que los desarrolladores sepan que deben dejar de utilizar la función o característica en cuestión para evitar errores y fallos en futuras versiones de Python.\n",
    "\n",
    "El objetivo principal es ayudar a los desarrolladores a actualizar su código para usar las nuevas funciones y características que reemplazan las obsoletas. Si no se actualiza el código, es posible que no funcione correctamente en futuras versiones de Python.\n",
    "\n",
    "Veamos un ejemplo:"
   ]
  },
  {
   "cell_type": "code",
   "execution_count": 5,
   "metadata": {},
   "outputs": [
    {
     "name": "stdout",
     "output_type": "stream",
     "text": [
      "El resultado es: 10\n",
      "El resultado es: 15\n"
     ]
    },
    {
     "name": "stderr",
     "output_type": "stream",
     "text": [
      "C:\\Users\\franc\\AppData\\Local\\Temp\\ipykernel_3104\\372299459.py:4: DeprecationWarning: Esta función está obsoleta, use multiplicar_por_n en su lugar\n",
      "  warnings.warn(\"Esta función está obsoleta, use multiplicar_por_n en su lugar\", DeprecationWarning)\n"
     ]
    }
   ],
   "source": [
    "import warnings\n",
    "\n",
    "def multiplicar_por_dos(numero):\n",
    "    warnings.warn(\"Esta función está obsoleta, use multiplicar_por_n en su lugar\", DeprecationWarning)\n",
    "    return numero * 2\n",
    "\n",
    "def multiplicar_por_n(numero, n):\n",
    "    return numero * n\n",
    "\n",
    "resultado = multiplicar_por_dos(5)\n",
    "print(\"El resultado es:\", resultado)\n",
    "\n",
    "resultado = multiplicar_por_n(5, 3)\n",
    "print(\"El resultado es:\", resultado)"
   ]
  },
  {
   "cell_type": "markdown",
   "metadata": {},
   "source": [
    "En este ejemplo, la función `multiplicar_por_dos` se ha quedado obsoleta y se emitirá una advertencia de tipo `DeprecationWarning` cuando se llame. La advertencia indicará que la función está obsoleta y que los desarrolladores deberían usar la función `multiplicar_por_n` en su lugar."
   ]
  },
  {
   "cell_type": "markdown",
   "metadata": {},
   "source": [
    "**FutureWarning**\n",
    "\n",
    "Es un tipo de advertencia que se utiliza para indicar que una característica o comportamiento del lenguaje o biblioteca puede cambiar en futuras versiones de Python. A diferencia de `DeprecationWarning`, `FutureWarning` no indica que una característica está obsoleta y se eliminará en futuras versiones, sino que simplemente indica que la forma en que se comporta actualmente podría cambiar en el futuro.\n",
    "\n",
    "Veamos un ejemplo:"
   ]
  },
  {
   "cell_type": "code",
   "execution_count": 11,
   "metadata": {},
   "outputs": [
    {
     "name": "stdout",
     "output_type": "stream",
     "text": [
      "El resultado es: 5\n"
     ]
    },
    {
     "name": "stderr",
     "output_type": "stream",
     "text": [
      "C:\\Users\\franc\\AppData\\Local\\Temp\\ipykernel_3104\\680115990.py:4: FutureWarning: La función sumar puede cambiar en futuras versiones\n",
      "  warnings.warn(\"La función sumar puede cambiar en futuras versiones\", FutureWarning)\n"
     ]
    }
   ],
   "source": [
    "import warnings\n",
    "\n",
    "def sumar(a, b):\n",
    "    warnings.warn(\"La función sumar puede cambiar en futuras versiones\", FutureWarning)\n",
    "    return a + b\n",
    "\n",
    "resultado = sumar(2, 3)\n",
    "print(\"El resultado es:\", resultado)"
   ]
  },
  {
   "cell_type": "markdown",
   "metadata": {},
   "source": [
    "En este ejemplo, la función `sumar` puede cambiar en futuras versiones, y se emite una advertencia de tipo `FutureWarning` al llamarla. La advertencia indica que la función podría cambiar en el futuro, lo que significa que el resultado podría ser diferente en una versión posterior de Python."
   ]
  },
  {
   "cell_type": "markdown",
   "metadata": {},
   "source": [
    "**RuntimeWarning**\n",
    "\n",
    "Es un tipo de advertencia que se utiliza para indicar que se ha producido un comportamiento inesperado durante la ejecución del programa. A diferencia de las excepciones, que son errores que interrumpen la ejecución del programa, las advertencias `RuntimeWarning` no interrumpen la ejecución, sino que simplemente indican que se ha producido un comportamiento inesperado.\n",
    "\n",
    "Veamos un ejemplo:"
   ]
  },
  {
   "cell_type": "code",
   "execution_count": 22,
   "metadata": {},
   "outputs": [
    {
     "name": "stdout",
     "output_type": "stream",
     "text": [
      "0.0\n"
     ]
    },
    {
     "name": "stderr",
     "output_type": "stream",
     "text": [
      "C:\\Users\\franc\\AppData\\Local\\Temp\\ipykernel_3104\\3819922338.py:2: RuntimeWarning: overflow encountered in exp\n",
      "  result = 1/(1+np.exp(1140))\n"
     ]
    }
   ],
   "source": [
    "import numpy as np\n",
    "result = 1/(1+np.exp(1140))\n",
    "print(result)"
   ]
  },
  {
   "cell_type": "markdown",
   "metadata": {},
   "source": [
    "En este ejemplo, `NumPy` realiza el cálculo (el resultado es `0,0`) pero aún imprime `RuntimeWarning`. Esta advertencia se imprime porque el valor `np.exp(1140)` representa $e^{1140}$, que es un número muy grande."
   ]
  },
  {
   "cell_type": "markdown",
   "metadata": {},
   "source": [
    "**UserWarning**\n",
    "\n",
    "Es un tipo de advertencia que se utiliza para indicar que se ha detectado una situación que puede no ser un error grave, pero que podría ser importante para el usuario final del programa.\n",
    "\n",
    "A diferencia de otras advertencias, como `DeprecationWarning` o `RuntimeWarning`, que se refieren a problemas técnicos en el código, `UserWarning` se utiliza para indicar al usuario que se ha producido una situación que puede requerir su atención o acción.\n",
    "\n",
    "Veamos un ejemplo:"
   ]
  },
  {
   "cell_type": "code",
   "execution_count": 14,
   "metadata": {},
   "outputs": [
    {
     "name": "stdout",
     "output_type": "stream",
     "text": [
      "El promedio de notas es: 7.0\n",
      "El promedio de notas es: None\n"
     ]
    },
    {
     "name": "stderr",
     "output_type": "stream",
     "text": [
      "C:\\Users\\franc\\AppData\\Local\\Temp\\ipykernel_3104\\3670255427.py:5: UserWarning: La lista de notas está vacía\n",
      "  warnings.warn(\"La lista de notas está vacía\", UserWarning)\n"
     ]
    }
   ],
   "source": [
    "import warnings\n",
    "\n",
    "def promedio_notas(notas):\n",
    "    if not notas:\n",
    "        warnings.warn(\"La lista de notas está vacía\", UserWarning)\n",
    "        return None\n",
    "    else:\n",
    "        return sum(notas) / len(notas)\n",
    "\n",
    "notas_estudiante = [7, 8, 6]\n",
    "promedio = promedio_notas(notas_estudiante)\n",
    "print(\"El promedio de notas es:\", promedio)\n",
    "\n",
    "notas_estudiante_vacias = []\n",
    "promedio = promedio_notas(notas_estudiante_vacias)\n",
    "print(\"El promedio de notas es:\", promedio)\n"
   ]
  },
  {
   "cell_type": "markdown",
   "metadata": {},
   "source": [
    "En este ejemplo, la función `promedio_notas` calcula el promedio de un conjunto de notas. Si la lista de notas está vacía, en lugar de devolver un error, se emite una advertencia utilizando el módulo warnings de Python con el mensaje \"La lista de notas está vacía\" y el tipo de advertencia `UserWarning`. Luego, la función devuelve `None`."
   ]
  },
  {
   "cell_type": "markdown",
   "metadata": {},
   "source": [
    "## Referencias\n",
    "\n",
    "* [Manejo de excepciones y errores en Python](https://www.datacamp.com/es/tutorial/exception-handling-python)"
   ]
  }
 ],
 "metadata": {
  "kernelspec": {
   "display_name": "Python 3 (ipykernel)",
   "language": "python",
   "name": "python3"
  },
  "language_info": {
   "codemirror_mode": {
    "name": "ipython",
    "version": 3
   },
   "file_extension": ".py",
   "mimetype": "text/x-python",
   "name": "python",
   "nbconvert_exporter": "python",
   "pygments_lexer": "ipython3",
   "version": "3.10.11"
  },
  "nbTranslate": {
   "displayLangs": [
    "*"
   ],
   "hotkey": "alt-t",
   "langInMainMenu": true,
   "sourceLang": "en",
   "targetLang": "fr",
   "useGoogleTranslate": true
  }
 },
 "nbformat": 4,
 "nbformat_minor": 4
}
